<?xml version="1.0"?>
<sdf version="1.6">
    <model name='vehicle_blue'>
        <pose>0 0 0.025 0 -0 0</pose>
        <link name='chassis'>
            <pose>0 0 0.025 0 0 0</pose>
            <inertial>
                <mass>1.14395</mass>
                <inertia>
                    <ixx>0.126164</ixx>
                    <ixy>0</ixy>
                    <ixz>0</ixz>
                    <iyy>0.416519</iyy>
                    <iyz>0</iyz>
                    <izz>0.481014</izz>
                </inertia>
            </inertial>
            <visual name='visual'>
                <geometry>
                    <box>
                        <size>0.1 0.05 0.05</size>
                    </box>
                </geometry>
                <material>
                    <ambient>0.5 0.5 1.0 1</ambient>
                    <diffuse>0.5 0.5 1.0 1</diffuse>
                    <specular>0.0 0.0 1.0 1</specular>
                </material>
            </visual>
            <collision name='collision'>
                <geometry>
                    <box>
                        <size>0.1 0.05 0.05</size>
                    </box>
                </geometry>
            </collision>
        </link>

        <link name='left_wheel'>
            <pose>0.05 0.025 0 -1.5707 0 0</pose>
            <inertial>
                <mass>2</mass>
                <inertia>
                    <ixx>0.145833</ixx>
                    <ixy>0</ixy>
                    <ixz>0</ixz>
                    <iyy>0.145833</iyy>
                    <iyz>0</iyz>
                    <izz>0.125</izz>
                </inertia>
            </inertial>
            <visual name='visual'>
                <geometry>
                    <sphere>
                        <radius>0.025</radius>
                    </sphere>
                </geometry>
                <material>
                    <ambient>0.2 0.2 0.2 1</ambient>
                    <diffuse>0.2 0.2 0.2 1</diffuse>
                    <specular>0.2 0.2 0.2 1</specular>
                </material>
            </visual>
            <collision name='collision'>
                <geometry>
                    <sphere>
                        <radius>0.025</radius>
                    </sphere>
                </geometry>
                <surface>
                    <friction>
                        <ode>
                            <mu>1</mu>
                            <mu2>1</mu2>
                            <slip1>0.035</slip1>
                            <slip2>0</slip2>
                            <fdir1>0 0 1</fdir1>
                        </ode>
                        <bullet>
                            <friction>1</friction>
                            <friction2>1</friction2>
                            <rolling_friction>0.1</rolling_friction>
                            <spinning_friction>0.1</spinning_friction>
                        </bullet>
                    </friction>
                </surface>
            </collision>
        </link>

        <link name='right_wheel'>
            <pose>0.05 -0.025 0 -1.5707 0 0</pose>
            <inertial>
                <mass>2</mass>
                <inertia>
                    <ixx>0.145833</ixx>
                    <ixy>0</ixy>
                    <ixz>0</ixz>
                    <iyy>0.145833</iyy>
                    <iyz>0</iyz>
                    <izz>0.125</izz>
                </inertia>
            </inertial>
            <visual name='visual'>
                <geometry>
                    <sphere>
                        <radius>0.025</radius>
                    </sphere>
                </geometry>
                <material>
                    <ambient>0.2 0.2 0.2 1</ambient>
                    <diffuse>0.2 0.2 0.2 1</diffuse>
                    <specular>0.2 0.2 0.2 1</specular>
                </material>
            </visual>
            <collision name='collision'>
                <geometry>
                    <sphere>
                        <radius>0.025</radius>
                    </sphere>
                </geometry>
                <surface>
                    <friction>
                        <ode>
                            <mu>1</mu>
                            <mu2>1</mu2>
                            <slip1>0.035</slip1>
                            <slip2>0</slip2>
                            <fdir1>0 0 1</fdir1>
                        </ode>
                        <bullet>
                            <friction>1</friction>
                            <friction2>1</friction2>
                            <rolling_friction>0.1</rolling_friction>
                            <spinning_friction>0.1</spinning_friction>
                        </bullet>
                    </friction>
                </surface>
            </collision>
        </link>

        <link name='caster'>
            <pose>-0.05 0 0 0 -0 0</pose>
            <inertial>
                <mass>1</mass>
                <inertia>
                    <ixx>0.1</ixx>
                    <ixy>0</ixy>
                    <ixz>0</ixz>
                    <iyy>0.1</iyy>
                    <iyz>0</iyz>
                    <izz>0.1</izz>
                </inertia>
            </inertial>
            <visual name='visual'>
                <geometry>
                    <sphere>
                        <radius>0.025</radius>
                    </sphere>
                </geometry>
                <material>
                    <ambient>0.2 0.2 0.2 1</ambient>
                    <diffuse>0.2 0.2 0.2 1</diffuse>
                    <specular>0.2 0.2 0.2 1</specular>
                </material>
            </visual>
            <collision name='collision'>
                <geometry>
                    <sphere>
                        <radius>0.025</radius>
                    </sphere>
                </geometry>
            </collision>
        </link>

        <joint name='left_wheel_joint' type='revolute'>
            <parent>chassis</parent>
            <child>left_wheel</child>
            <axis>
                <xyz>0 0 1</xyz>
                <limit>
                    <lower>-1.79769e+308</lower>
                    <upper>1.79769e+308</upper>
                </limit>
            </axis>
        </joint>

        <joint name='right_wheel_joint' type='revolute'>
            <parent>chassis</parent>
            <child>right_wheel</child>
            <axis>
                <xyz>0 0 1</xyz>
                <limit>
                    <lower>-1.79769e+308</lower>
                    <upper>1.79769e+308</upper>
                </limit>
            </axis>
        </joint>

        <joint name='caster_wheel' type='ball'>
            <parent>chassis</parent>
            <child>caster</child>
        </joint>

        <link name='sensor'>
            <pose>0 0 0.06 0 0 0</pose>

            <sensor name="camera" type="camera">
                <camera>
                    <horizontal_fov>1.047</horizontal_fov>
                    <image>
                        <width>320</width>
                        <height>240</height>
                    </image>
                    <clip>
                        <near>0.1</near>
                        <far>100</far>
                    </clip>
                </camera>
                <always_on>1</always_on>
                <update_rate>30</update_rate>
                <visualize>true</visualize>
                <topic>camera</topic>
                <enable_metrics>true</enable_metrics>
            </sensor>

            <sensor name="depth_camera" type="depth_camera">
                <update_rate>10</update_rate>
                <topic>depth_camera</topic>
                <enable_metrics>true</enable_metrics>
                <camera>
                    <horizontal_fov>1.05</horizontal_fov>
                    <image>
                        <width>320</width>
                        <height>240</height>
                        <format>R_FLOAT32</format>
                    </image>
                    <clip>
                        <near>0.1</near>
                        <far>10.0</far>
                    </clip>
                </camera>
            </sensor>

            <sensor name="rgbd_camera" type="rgbd_camera">
                <camera>
                    <horizontal_fov>1.047</horizontal_fov>
                    <image>
                        <width>320</width>
                        <height>240</height>
                    </image>
                    <clip>
                        <near>0.1</near>
                        <far>100</far>
                    </clip>
                </camera>
                <always_on>1</always_on>
                <update_rate>30</update_rate>
                <visualize>true</visualize>
                <topic>rgbd_camera</topic>
                <enable_metrics>true</enable_metrics>
            </sensor>

            <sensor name="thermal_camera" type="thermal_camera">
                <camera>
                    <horizontal_fov>1.047</horizontal_fov>
                    <image>
                        <width>320</width>
                        <height>240</height>
                    </image>
                    <clip>
                        <near>0.1</near>
                        <far>100</far>
                    </clip>
                </camera>
                <always_on>1</always_on>
                <update_rate>30</update_rate>
                <visualize>true</visualize>
                <topic>thermal_camera</topic>
            </sensor>

            <sensor name='gpu_lidar' type='gpu_lidar'>
                <topic>lidar</topic>
                <update_rate>10</update_rate>
                <enable_metrics>true</enable_metrics>
                <ray>
                    <scan>
                        <horizontal>
                            <samples>640</samples>
                            <resolution>1</resolution>
                            <min_angle>-1.396263</min_angle>
                            <max_angle>1.396263</max_angle>
                        </horizontal>
                        <vertical>
                            <samples>1</samples>
                            <resolution>0.01</resolution>
                            <min_angle>0</min_angle>
                            <max_angle>0</max_angle>
                        </vertical>
                    </scan>
                    <range>
                        <min>0.08</min>
                        <max>10.0</max>
                        <resolution>0.01</resolution>
                    </range>
                </ray>
                <alwaysOn>1</alwaysOn>
                <visualize>true</visualize>
            </sensor>

            <sensor name="altimeter" type="altimeter">
                <always_on>1</always_on>
                <update_rate>30</update_rate>
                <visualize>true</visualize>
                <topic>altimeter</topic>
                <enable_metrics>true</enable_metrics>
                <altimeter>
                    <vertical_position>
                        <noise type="gaussian">
                            <mean>0.1</mean>
                            <stddev>0.2</stddev>
                        </noise>
                    </vertical_position>
                    <vertical_velocity>
                        <noise type="gaussian">
                            <mean>0.2</mean>
                            <stddev>0.1</stddev>
                        </noise>
                    </vertical_velocity>
                </altimeter>
            </sensor>

            <sensor name="air_pressure" type="air_pressure">
                <always_on>1</always_on>
                <update_rate>30</update_rate>
                <visualize>true</visualize>
                <topic>air_pressure</topic>
                <enable_metrics>true</enable_metrics>
                <air_pressure>
                    <reference_altitude>123</reference_altitude>
                    <pressure>
                        <noise type="gaussian">
                            <mean>0.2</mean>
                            <stddev>0.1</stddev>
                        </noise>
                    </pressure>
                </air_pressure>
            </sensor>

            <sensor name="imu" type="imu">
                <always_on>1</always_on>
                <update_rate>100</update_rate>
                <visualize>true</visualize>
                <topic>imu</topic>
                <enable_metrics>true</enable_metrics>
            </sensor>

            <sensor name="magnetometer" type="magnetometer">
                <always_on>1</always_on>
                <update_rate>100</update_rate>
                <visualize>true</visualize>
                <topic>magnetometer</topic>
                <enable_metrics>true</enable_metrics>
                <magnetometer>
                    <x>
                        <noise type="gaussian">
                            <mean>0.0</mean>
                            <stddev>0.1</stddev>
                        </noise>
                    </x>
                    <y>
                        <noise type="gaussian">
                            <mean>0.0</mean>
                            <stddev>0.1</stddev>
                        </noise>
                    </y>
                    <z>
                        <noise type="gaussian">
                            <mean>0.0</mean>
                            <stddev>0.1</stddev>
                        </noise>
                    </z>
                </magnetometer>
            </sensor>

            <sensor name="force_torque" type="force_torque">
                <update_rate>10</update_rate>
            </sensor>
        </link>
        <joint name='sensor_joint' type='fixed'>
            <parent>chassis</parent>
            <child>sensor</child>
        </joint>

        <plugin
            filename="gz-sim-diff-drive-system"
            name="gz::sim::systems::DiffDrive">
            <left_joint>left_wheel_joint</left_joint>
            <right_joint>right_wheel_joint</right_joint>
            <!-- commenting this as it will not work with multiple model 
            <topic>cmd_vel</topic>
            <odom_topic>vehicle_blue/odom</odom_topic> 
            -->
            <tf_topic>tf</tf_topic>
            <wheel_separation>1.25</wheel_separation>
            <wheel_radius>0.3</wheel_radius>
            <odom_publish_frequency>1</odom_publish_frequency>
            <max_linear_acceleration>1</max_linear_acceleration>
            <min_linear_acceleration>-1</min_linear_acceleration>
            <max_angular_acceleration>2</max_angular_acceleration>
            <min_angular_acceleration>-2</min_angular_acceleration>
            <max_linear_velocity>0.5</max_linear_velocity>
            <min_linear_velocity>-0.5</min_linear_velocity>
            <max_angular_velocity>1</max_angular_velocity>
            <min_angular_velocity>-1</min_angular_velocity>
        </plugin>

    </model>
</sdf>