<?xml version="1.0"?>
<sdf version="1.6">
  <world name="turtlebot3_house">
    <scene>
      <ambient>1.0 1.0 1.0</ambient>
      <background>0.8 0.8 0.8</background>
    </scene>

    <plugin
      filename="gz-sim-physics-system"
      name="gz::sim::systems::Physics"></plugin>
    <plugin
      filename="gz-sim-user-commands-system"
      name="gz::sim::systems::UserCommands"></plugin>
    <plugin
      filename="gz-sim-scene-broadcaster-system"
      name="gz::sim::systems::SceneBroadcaster"></plugin>
    <plugin
      filename="libgz-sim-sensors-system.so"
      name="gz::sim::systems::Sensors">
      <render_engine>ogre2</render_engine>
    </plugin>
    <plugin filename="libignition-gazebo-imu-system.so"
      name="ignition::gazebo::systems::Imu"></plugin>

    <light type="directional" name="sun">
      <cast_shadows>true</cast_shadows>
      <pose>0 0 10 0 0 0</pose>
      <diffuse>0.8 0.8 0.8 1</diffuse>
      <specular>0.2 0.2 0.2 1</specular>
      <attenuation>
        <range>1000</range>
        <constant>0.9</constant>
        <linear>0.01</linear>
        <quadratic>0.001</quadratic>
      </attenuation>
      <direction>-0.5 0.1 -0.9</direction>
    </light>

    <model name="ground_plane">
      <static>true</static>
      <link name="link">
        <collision name="collision">
          <geometry>
            <plane>
              <normal>0.0 0.0 1</normal>
            </plane>
          </geometry>
        </collision>
        <visual name="visual">
          <geometry>
            <plane>
              <normal>0.0 0.0 1</normal>
              <size>100 100</size>
            </plane>
          </geometry>
          <material>
            <ambient>0.8 0.8 0.8 1</ambient>
            <diffuse>0.8 0.8 0.8 1</diffuse>
            <specular>0.8 0.8 0.8 1</specular>
          </material>
        </visual>
      </link>
    </model>

    <model name="turtlebot3_house">
      <static>1</static>
      <include>
        <uri>model://turtlebot3_house</uri>
      </include>
    </model>
    <model name="turtlebot3_burger">
      <pose>-2.0 2.0 0.0 0.0 0.0 0.0</pose>

      <link name="base_footprint" />

      <link name="base_link">

        <inertial>
          <pose>-0.032 0 0.0 0 0 0</pose>
          <!-- <pose>-0.032 0 0.070 0 0 0</pose> -->
          <inertia>
            <ixx>7.2397393e-01</ixx>
            <ixy>4.686399e-10</ixy>
            <ixz>-1.09525703e-08</ixz>
            <iyy>7.2397393e-01</iyy>
            <iyz>2.8582649e-09</iyz>
            <izz>6.53050163e-01</izz>
          </inertia>
          <mass>8.2573504</mass>
          <!-- <mass>8.2573504</mass> -->
        </inertial>

        <collision name="base_collision">
          <pose>-0.032 0 0.070 0 0 0</pose>
          <geometry>
            <box>
              <size>0.140 0.140 0.140</size>
            </box>
          </geometry>
        </collision>

        <visual name="base_visual">
          <pose>-0.032 0 0 0 0 0</pose>
          <geometry>
            <mesh>
              <uri>model://turtlebot3_common/meshes/burger/base.stl</uri>
              <scale>0.001 0.001 0.001</scale>
            </mesh>
          </geometry>
          <material>
            <ambient>0.2 0.2 0.2 1</ambient>
            <diffuse>0.2 0.2 0.2 1</diffuse>
            <specular>0.2 0.2 0.2 1</specular>
          </material>
        </visual>
      </link>

      <link name="imu_link">
        <sensor name="imu_sensor" type="imu">
          <always_on>1</always_on>
          <update_rate>1</update_rate>
          <visualize>true</visualize>
          <topic>imu</topic>
          <angular_velocity>
            <x>
              <noise type="gaussian">
                <mean>0.0</mean>
                <stddev>2e-4</stddev>
              </noise>
            </x>
            <y>
              <noise type="gaussian">
                <mean>0.0</mean>
                <stddev>2e-4</stddev>
              </noise>
            </y>
            <z>
              <noise type="gaussian">
                <mean>0.0</mean>
                <stddev>2e-4</stddev>
              </noise>
            </z>
          </angular_velocity>
          <linear_acceleration>
            <x>
              <noise type="gaussian">
                <mean>0.0</mean>
                <stddev>1.7e-2</stddev>
              </noise>
            </x>
            <y>
              <noise type="gaussian">
                <mean>0.0</mean>
                <stddev>1.7e-2</stddev>
              </noise>
            </y>
            <z>
              <noise type="gaussian">
                <mean>0.0</mean>
                <stddev>1.7e-2</stddev>
              </noise>
            </z>
          </linear_acceleration>
          <!-- <orientation_reference_frame>
            <localization></localization>
          </orientation_reference_frame> -->
        </sensor>
      </link>

      <link name="base_scan">
        <inertial>
          <pose>-0.020 0 0.161 0 0 0</pose>
          <inertia>
            <ixx>0.001</ixx>
            <ixy>0.000</ixy>
            <ixz>0.000</ixz>
            <iyy>0.001</iyy>
            <iyz>0.000</iyz>
            <izz>0.001</izz>
          </inertia>
          <mass>0.114</mass>
        </inertial>

        <collision name="lidar_sensor_collision">
          <pose>-0.020 0 0.161 0 0 0</pose>
          <geometry>
            <cylinder>
              <radius>0.0508</radius>
              <length>0.055</length>
            </cylinder>
          </geometry>
        </collision>

        <visual name="lidar_sensor_visual">
          <pose>-0.032 0 0.171 0 0 0</pose>
          <geometry>
            <mesh>
              <uri>model://turtlebot3_common/meshes/burger/ladar.stl</uri>
              <scale>0.001 0.001 0.001</scale>
            </mesh>
          </geometry>
          <material>
            <ambient>0.8 0.8 0.8 1</ambient>
            <diffuse>0.8 0.8 0.8 1</diffuse>
            <specular>0.8 0.8 0.8 1</specular>
          </material>
        </visual>

        <sensor name="hls_lfcd_lds" type="gpu_lidar">
          <always_on>true</always_on>
          <visualize>true</visualize>
          <update_rate>10</update_rate>
          <topic>lidar</topic>
          <pose>-0.032 0 0.171 0 0 0</pose>
          <ray>
            <scan>
              <horizontal>
                <samples>360</samples>
                <resolution>1.000000</resolution>
                <min_angle>0.000000</min_angle>
                <max_angle>6.28319</max_angle>
              </horizontal>
              <vertical>
                <samples>1</samples>
                <resolution>0.01</resolution>
                <min_angle>0</min_angle>
                <max_angle>0</max_angle>
              </vertical>
            </scan>
            <range>
              <min>0.120000</min>
              <max>10</max>
              <resolution>0.015000</resolution>
            </range>
            <noise>
              <type>gaussian</type>
              <mean>0.0</mean>
              <stddev>0.01</stddev>
            </noise>
          </ray>
        </sensor>
      </link>

      <link name="wheel_left_link">

        <inertial>
          <pose>0 0.08 0.023 -1.57 0 0</pose>
          <inertia>
            <ixx>1.8158194e-03</ixx>
            <ixy>-9.3392e-12</ixy>
            <ixz>1.04909e-11</ixz>
            <iyy>3.2922126e-03</iyy>
            <iyz>5.75694e-11</iyz>
            <izz>1.8158194e-03</izz>
          </inertia>
          <mass>2.8498940e-02</mass>
        </inertial>

        <collision name="wheel_left_collision">
          <pose>0 0.08 0.023 -1.57 0 0</pose>
          <geometry>
            <cylinder>
              <radius>0.033</radius>
              <length>0.018</length>
            </cylinder>
          </geometry>
          <surface>
            <friction>
              <ode>
                <mu>1</mu>
                <mu2>1</mu2>
                <slip1>0.035</slip1>
                <slip2>0</slip2>
                <fdir1>0 0 1</fdir1>
              </ode>
              <bullet>
                <friction>1</friction>
                <friction2>1</friction2>
                <rolling_friction>0.1</rolling_friction>
                <spinning_friction>0.1</spinning_friction>
              </bullet>
            </friction>
            <contact>
              <ode>
                <soft_cfm>0</soft_cfm>
                <soft_erp>0.2</soft_erp>
                <kp>500000</kp>
                <kd>10</kd>
                <max_vel>1</max_vel>
                <min_depth>0.001</min_depth>
              </ode>
            </contact>
          </surface>
        </collision>

        <visual name="wheel_left_visual">
          <pose>0 0.08 0.023 0 0 0</pose>
          <geometry>
            <mesh>
              <uri>model://turtlebot3_common/meshes/burger/left_tire.stl</uri>
              <scale>0.001 0.001 0.001</scale>
            </mesh>
          </geometry>
          <material>
            <ambient>0.8 0.8 0.8 1</ambient>
            <diffuse>0.8 0.8 0.8 1</diffuse>
            <specular>0.8 0.8 0.8 1</specular>
          </material>
        </visual>
      </link>

      <link name="wheel_right_link">

        <inertial>
          <pose>0.0 -0.08 0.023 -1.57 0 0</pose>
          <inertia>
            <ixx>1.8158194e-03</ixx>
            <ixy>-9.3392e-12</ixy>
            <ixz>1.04909e-11</ixz>
            <iyy>3.2922126e-03</iyy>
            <iyz>5.75694e-11</iyz>
            <izz>1.8158194e-03</izz>
          </inertia>
          <mass>2.8498940e-02</mass>
        </inertial>

        <collision name="wheel_right_collision">
          <pose>0.0 -0.08 0.023 -1.57 0 0</pose>
          <geometry>
            <cylinder>
              <radius>0.033</radius>
              <length>0.018</length>
            </cylinder>
          </geometry>
          <surface>
            <friction>
              <ode>
                <mu>1</mu>
                <mu2>1</mu2>
                <slip1>0.035</slip1>
                <slip2>0</slip2>
                <fdir1>0 0 1</fdir1>
              </ode>
              <bullet>
                <friction>1</friction>
                <friction2>1</friction2>
                <rolling_friction>0.1</rolling_friction>
                <spinning_friction>0.1</spinning_friction>
              </bullet>
            </friction>
            <contact>
              <ode>
                <soft_cfm>0</soft_cfm>
                <soft_erp>0.2</soft_erp>
                <kp>500000</kp>
                <kd>10</kd>
                <max_vel>1</max_vel>
                <min_depth>0.001</min_depth>
              </ode>
            </contact>
          </surface>
        </collision>

        <visual name="wheel_right_visual">
          <pose>0.0 -0.08 0.023 0 0 0</pose>
          <geometry>
            <mesh>
              <uri>model://turtlebot3_common/meshes/burger/right_tire.stl</uri>
              <scale>0.001 0.001 0.001</scale>
            </mesh>
          </geometry>
          <material>
            <ambient>0.8 0.8 0.8 1</ambient>
            <diffuse>0.8 0.8 0.8 1</diffuse>
            <specular>0.8 0.8 0.8 1</specular>
          </material>
        </visual>
      </link>

      <link name='caster_back_link'>
        <pose>-0.081 0 -0.004 -1.57 0 0</pose>
        <!-- <inertial>
          <mass>0.005</mass>
          <inertia>
            <ixx>0.001</ixx>
            <ixy>0.000</ixy>
            <ixz>0.000</ixz>
            <iyy>0.001</iyy>
            <iyz>0.000</iyz>
            <izz>0.001</izz>
          </inertia>
        </inertial> -->
        <collision name='collision'>
          <geometry>
            <sphere>
              <radius>0.005000</radius>
            </sphere>
          </geometry>
          <!-- <surface>
            <contact>
              <ode>
                <soft_cfm>0</soft_cfm>
                <soft_erp>0.2</soft_erp>
                <kp>500000</kp>
                <kd>10</kd>
                <max_vel>1</max_vel>
                <min_depth>0.001</min_depth>
              </ode>
            </contact>
          </surface> -->
        </collision>
      </link>

      <joint name="base_joint" type="fixed">
        <parent>base_footprint</parent>
        <child>base_link</child>
        <pose>0.0 0.0 0.010 0 0 0</pose>
      </joint>

      <joint name="wheel_left_joint" type="revolute">
        <parent>base_link</parent>
        <child>wheel_left_link</child>
        <pose>0.0 0.08 0.023 -1.57 0 0</pose>
        <axis>
          <xyz>0 0 1</xyz>
        </axis>
      </joint>

      <joint name="wheel_right_joint" type="revolute">
        <parent>base_link</parent>
        <child>wheel_right_link</child>
        <pose>0.0 -0.08 0.023 -1.57 0 0</pose>
        <axis>
          <xyz>0 0 1</xyz>
        </axis>
      </joint>

      <joint name='caster_back_joint' type='ball'>
        <parent>base_link</parent>
        <child>caster_back_link</child>
      </joint>

      <joint name="imu_joint" type="fixed">
        <parent>base_link</parent>
        <child>imu_link</child>
        <pose>-0.032 0 0.068 0 0 0</pose>
        <axis>
          <xyz>0 0 1</xyz>
        </axis>
      </joint>

      <joint name="lidar_joint" type="fixed">
        <parent>base_link</parent>
        <child>base_scan</child>
        <pose>-0.032 0 0.171 0 0 0</pose>
        <axis>
          <xyz>0 0 1</xyz>
        </axis>
      </joint>

      <plugin name="gz::sim::systems::DiffDrive" filename="gz-sim-diff-drive-system">
        <update_rate>30</update_rate>

        <!-- wheels -->
        <left_joint>wheel_left_joint</left_joint>
        <right_joint>wheel_right_joint</right_joint>

        <!-- kinematics -->
        <wheel_separation>0.160</wheel_separation>
        <wheel_radius>0.033</wheel_radius>

        <!-- <min_acceleration></min_acceleration>
        <max_acceleration>1</max_acceleration>
         -->
        <topic>cmd_vel</topic>
        <odometry_topic>odom</odometry_topic>
        <odometry_frame>odom</odometry_frame>
      </plugin>
      <plugin
        filename="gz-sim-pose-publisher-system"
        name="gz::sim::systems::PosePublisher">
        <publish_link_pose>true</publish_link_pose>
        <publish_sensor_pose>true</publish_sensor_pose>
        <publish_collision_pose>false</publish_collision_pose>
        <publish_visual_pose>false</publish_visual_pose>
        <publish_nested_model_pose>false</publish_nested_model_pose>
      </plugin>
    </model>
  </world>
</sdf>